## _Обработка ошибок_

- `try..catch` работает синхронно. 

Поэтому исключение, которое произойдёт в коде, запланированном «на будущее» (например в `setTimeout`), `try..catch` не поймает. Тк функция выполняется позже, когда движок уже покинул конструкцию `try..catch`.

Чтобы `поймать исключение` внутри запланированной функции, `try..catch` должен находиться внутри самой этой функции:

``` 
setTimeout(function() {
  try {
    noSuchVariable; // try..catch обрабатывает ошибку!
  } catch {
    console.log( "ошибка поймана!" );
  }
}, 1000);
```

### _try..finally_

Конструкция `try..finally` без секции `catch` также полезна. Мы применяем её, когда не хотим здесь обрабатывать ошибки (пусть выпадут), но хотим быть уверены, что начатые процессы завершились.

``` 
function func() {
  // начать делать что-то, что требует завершения (например, измерения)
  try {
    // ...
  } finally {
    // завершить это, даже если все упадёт
  }
}
```

### _Объект ошибки_

Когда возникает `ошибка`, JavaScript `генерирует` `объект-экземпляр` от конструктора `Error`, содержащий её детали. 
Затем этот `объект` передаётся как `аргумент` в блок `catch`:

```
try {
  console.log(undefVar);
} catch (error) {
  console.log(error.name);     /=/ Имя ошибки
                                  (в данном случае "ReferenceError")
  console.log(error.message);  /=/ Сообщение об ошибке
																  (в данном случае "undefVar is not defined")
  console.log(error.stack);    /=/ Стек вызовов.
																  Содержит информацию о месте, где произошла ошибка.
}
```
#стек_вызовов

`Стек вызовов` представляет собой `список` функций и методов, ***которые были вызваны перед возникновением `ошибки`***.

### _Проброс исключений_

Для его реализации нам достаточно проверить во внутреннем блоке `catch` тип ошибки и, если она не соответствует `Error`, то передать дальше:

```
// let res = 0;
try {
  res = divide(1, 2);
  console.log(res);
} catch (error) {
  if (error.name == "Error") {
    console.log(error.name);
    console.log(error.message);
  } else {
    throw error; /=/ Проброс ошибки наверх
  }
}
```

Соответственно, внутри будет обрабатывать только исключения `Error`, а остальные пробрасывать блокам более высокого уровня.

```
try {
    return getData(key);
} catch (error) {
    if (error instanceof NotFoundError) {
      throw error; /=/ Проброс ошибки наверх
    }
}
```
#проброс_ошибки_наверх

### _Создание пользовательских Error_

Создадим функцию `readUser(json)` которая будет не только читать `JSON-данные`, но и проверять их (`валидировать`). 
Если необходимые поля `отсутствуют` или данные в `неверном формате`, мы будем считать это ошибкой `ошибкой`. 

Назовём её ошибкой валидации `ValidationError` и создадим для неё класс. `Ошибка` этого вида должна содержать `информацию о поле`, которое является `источником ошибки`.

Наш класс `ValidationError` должен наследовать от встроенного класса `Error`.
Примерно так выглядит встроенный класс `Error`, от которого мы будем расширяться:

``` 
class Error {
  constructor(message) {
    this.message = message;
    this.name = "Error";
    this.stack = <стек вызовов> 
  }
}
```

```
class ValidationError extends Error {
  constructor(message) {
    super(message);
    this.name = "ValidationError"; 
  }
}

// Использование

function readUser(json) {
  let user = JSON.parse(json);

  if (!user.age) {
    throw new ValidationError("Нет поля: age");
  }
  if (!user.name) {
    throw new ValidationError("Нет поля: name");
  }
  return user;
}

// Рабочий пример с try..catch

try {
  let user = readUser('{ "age": 25 }');
} catch (err) {
  if (err instanceof ValidationError) {
    console.log("Некорректные данные: " + err.message);
    /=/ Некорректные данные: Нет поля: name
  } else if (err instanceof SyntaxError) {
    console.log("JSON Ошибка Синтаксиса: " + err.message);
  } else {
    throw err;
    /=/ Неизвестная ошибка, пробросить исключение
  }
}
```
#обработка_исключений

## _Асинхронность_

### _Вложенный setTimeout_

Вложенный `setTimeout` – более гибкий метод, чем `setInterval`. 
Также он позволяет `более точно` задать `интервал` между выполнениями.

```
// Вместо: let timerId = setInterval(() => console.log('tick'), 2000);  
  
const tick = () => {  
  console.log("tick");  
  timerId = setTimeout(tick, 2000);  
};  
  
let timerId = setTimeout(tick, 2000);
```

-> Например, необходимо написать сервис, который отправляет запрос для получения данных на сервер каждые 5 секунд, но если сервер перегружен, то необходимо увеличить интервал запросов до 10, 20, 40 секунд…

``` 
let delay = 5000;

let timerId = setTimeout(function request() {
  ...отправить запрос...

  if (ошибка запроса из-за перегрузки сервера) {
    delay *= 2; 
    /=/ Увеличить интервал для следующего запроса
  }
  
  timerId = setTimeout(request, delay);
  
}, delay);
```

### _Callback_

![[callback]]

---
Переписывание асинхронного `коллбэка` в приемлемый вид

```
async function pageLoader(callback) {
  const data = await fetch("https://jsonplaceholder.typicode.com/todos/1");
  callback(data);
}

function pageLoader(callback) {
  fetch("https://jsonplaceholder.typicode.com/todos/1")
    .then((response) => response.json())
    .then((data) => callback(data))
    .catch((error) => console.error(error));
}

async function pageLoader(callback) {
  try {
    const response = await fetch("https://jsonplaceholder.typicode.com/todos/1");
    const json = await response.json();
    callback(json);
  } catch (error) {
    console.error(error);
  }
}

function getAjax(data) {
  console.log("Запрос послан");
  console.log("Ответ сервера");
  console.log(data);
}

pageLoader(getAjax);
```

### _Promise_

![[promises]]

### _Async/await_

- Функция которая является `async`( `асинхронной`) - всегда возвращает `return promise`
Тк внутри все работает на промисах и колбэках.

```
async function fetchAsyncTodos() {  
  console.log("Fetch todo started...");  
  await delay(2000); /=/ (**)
  const response = await fetch(url);  
  const data = await response.json();  
  console.log("Data:", data);  
}
```

`** await` - позволяет не переходить к следующей сточке, пока `promise` на текущей строчки не выполнится

## _Асинхронные циклы_

```
async function processArray(array) {
  array.forEach(item => {
    // тут мы определили синхронную анонимную функцию
    // НО ЭТО КОД ВЫДАСТ ОШИБКУ!
    await func(item);
  })
}
```

Этот код выдаст ошибку. Почему? Потому что мы не можем использовать `await` внутри синхронной функции. Как вы можете видеть `processArray` — это асинхронная функция. Но анонимная функция, которую мы используем для `forEach`, является **синхронной**.

### _Способы решения_

### _Обработка цикла последовательно_

- Позволяет дождаться выполнения функции `delayedLog(item)` и ее завершения, прежде чем перейти к следующей итерации цикла.

```
async function processArray(array) {
  for (const item of array) {
    await delayedLog(item);
  }
  console.log('Done!');
}
```

```
async function increaseSalary() {  
  const increasedWorkers = [];  
  
  try {  
    const workers = await api.getEmployees();  
    const salaryAvg =  
      workers.reduce((acc, el) => acc + el.salary, 0) / workers.length;  
  
    for (let { id, name, salary } of workers) {  
      try {  
        const newSalary = salary < salaryAvg ? salary * 1.2 : salary * 1.1;  
        const increased = await api.setEmployeeSalary(id, newSalary);  
  
        await api.notifyEmployee(id, `${name}, your new salary is ${newSalary}!`);  
        increasedWorkers.push(increased);  
      } catch (error) {  
        await api.notifyAdmin(error);  
      }  
    }  
    
  } catch (error) {  
    api.notifyAdmin(error);  
  } finally {  
    const increasedSum = increasedWorkers.reduce((acc, el) => {  
      return acc + el.salary;  
    }, 0);  
    api.sendBudgetToAccounting(increasedSum);  
    return increasedWorkers.length;  
  }  
}
```
 
### _Обработка цикла параллельно_

Такой подход может запустить несколько `delayLog` задач параллельно. Но будьте аккуратны с большими массивами. Слишком много задач может быть слишком тяжело для CPU и памяти.

```
async function processArray(array) {
  const promises = array.map(delayedLog); /=/ Создаем массив промисов
  await Promise.all(promises); /=/ Ждем когда всё промисы будут выполнены
  console.log('Done!');
}
```
---

**-> C использованием `await`** *(последовательно)*
```
async function processArray(array) {
  await Promise.all(array.map(async (item) => await func(item))); /=/ (*)
  console.log('Done!');
}
```

`* await` перед вызовом `func(item)` - код будет ждать, пока каждый вызов `func(item)` завершится, прежде чем перейти к следующей итерации цикла `map`.

**-> Без использования `await`** *(параллельно)*
```
async function processArray(array) {
  await Promise.all(array.map((item) => func(item)));
  console.log('Done!');
}
```

Во втором варианте, где не используется `await` перед вызовом `func(item)`, каждый вызов `func(item)` будет запущен параллельно, без ожидания завершения предыдущего вызова. Это может быть полезно, если вам не важен порядок выполнения и вы хотите запустить все вызовы `func(item)` одновременно.

---
Когда мы используем `Promise.all()` вместе с `array.map()`, мы создаем массив промисов, каждый из которых представляет асинхронную операцию `func(item)` для каждого элемента `array`.

`Promise.all()` ожидает разрешения всех промисов в массиве. Это означает, что код будет приостановлен, пока все асинхронные операции не завершатся.

Когда все промисы разрешаются, это означает, что все асинхронные операции `func(item)` в цикле `array.map()` завершены.

После этого, код после `await Promise.all()` будет выполнен. В данном случае, это `console.log('Done!')`, которое выводит сообщение "Done!" в консоль.

---
### _Определить анонимную функцию как асинхронную:_

**-> Не сработает корректно**
```
async function processArray(array) {
  array.forEach(async (item) => {
    await func(item);
  })
  console.log('Done!');
}
```

`forEach` не будет дожидаться выполнения завершения задачи. `forEach` — синхронная операция. Она просто запустит задачи и пойдет дальше.  
___
## _Event Loop_

![[event_loop]]

## _Throttle & Debounce_

![[trottle & debounce]]
 
